<?xml version="1.0" encoding="UTF-8"?>
<!-- Generated by org.testng.reporters.JUnitReportReporter -->
<testsuite hostname="LP-5CG1225D1D" name="com.example1.calculateTest$calcTest" tests="4" failures="1" timestamp="4 Aug 2021 19:04:33 GMT" time="0.019" errors="1">
  <testcase name="mulTest" time="0.001" classname="com.example1.calculateTest$calcTest"/>
  <testcase name="mulTest" time="0.004" classname="com.example1.calculateTest$calcTest">
    <failure type="java.lang.AssertionError" message="expected [9] but found [10]">
      <![CDATA[java.lang.AssertionError: expected [9] but found [10]
	at org.testng.Assert.fail(Assert.java:94)
	at org.testng.Assert.failNotEquals(Assert.java:496)
	at org.testng.Assert.assertEquals(Assert.java:125)
	at org.testng.Assert.assertEquals(Assert.java:372)
	at org.testng.Assert.assertEquals(Assert.java:382)
	at com.example1.calculateTest$calcTest.mulTest(calculateTest.java:15)
	at sun.reflect.NativeMethodAccessorImpl.invoke0(Native Method)
	at sun.reflect.NativeMethodAccessorImpl.invoke(NativeMethodAccessorImpl.java:62)
	at sun.reflect.DelegatingMethodAccessorImpl.invoke(DelegatingMethodAccessorImpl.java:43)
	at java.lang.reflect.Method.invoke(Method.java:498)
	at org.testng.internal.MethodInvocationHelper.invokeMethod(MethodInvocationHelper.java:85)
	at org.testng.internal.Invoker.invokeMethod(Invoker.java:663)
	at org.testng.internal.Invoker.invokeTestMethod(Invoker.java:849)
	at org.testng.internal.Invoker.invokeTestMethods(Invoker.java:1157)
	at org.testng.internal.TestMethodWorker.invokeTestMethods(TestMethodWorker.java:124)
	at org.testng.internal.TestMethodWorker.run(TestMethodWorker.java:108)
	at org.testng.TestRunner.privateRun(TestRunner.java:771)
	at org.testng.TestRunner.run(TestRunner.java:621)
	at org.testng.SuiteRunner.runTest(SuiteRunner.java:357)
	at org.testng.SuiteRunner.runSequentially(SuiteRunner.java:352)
	at org.testng.SuiteRunner.privateRun(SuiteRunner.java:310)
	at org.testng.SuiteRunner.run(SuiteRunner.java:259)
	at org.testng.SuiteRunnerWorker.runSuite(SuiteRunnerWorker.java:52)
	at org.testng.SuiteRunnerWorker.run(SuiteRunnerWorker.java:86)
	at org.testng.TestNG.runSuitesSequentially(TestNG.java:1200)
	at org.testng.TestNG.runSuitesLocally(TestNG.java:1125)
	at org.testng.TestNG.run(TestNG.java:1033)
	at org.testng.remote.RemoteTestNG.run(RemoteTestNG.java:111)
	at org.testng.remote.RemoteTestNG.initAndRun(RemoteTestNG.java:204)
	at org.testng.remote.RemoteTestNG.main(RemoteTestNG.java:175)
]]>
    </failure>
  </testcase> <!-- mulTest -->
  <testcase name="subTest" time="0.001" classname="com.example1.calculateTest$calcTest">
    <error type="org.testng.TestException" message="
Method calculateTest$calcTest.subTest()[pri:0, instance:com.example1.calculateTest$calcTest@75412c2f] should have thrown an exception of type class java.lang.ArithmeticException">
      <![CDATA[org.testng.TestException: 
Method calculateTest$calcTest.subTest()[pri:0, instance:com.example1.calculateTest$calcTest@75412c2f] should have thrown an exception of type class java.lang.ArithmeticException
	at org.testng.internal.Invoker.handleInvocationResults(Invoker.java:1428)
	at org.testng.internal.Invoker.invokeMethod(Invoker.java:705)
	at org.testng.internal.Invoker.invokeTestMethod(Invoker.java:849)
	at org.testng.internal.Invoker.invokeTestMethods(Invoker.java:1157)
	at org.testng.internal.TestMethodWorker.invokeTestMethods(TestMethodWorker.java:124)
	at org.testng.internal.TestMethodWorker.run(TestMethodWorker.java:108)
	at org.testng.TestRunner.privateRun(TestRunner.java:771)
	at org.testng.TestRunner.run(TestRunner.java:621)
	at org.testng.SuiteRunner.runTest(SuiteRunner.java:357)
	at org.testng.SuiteRunner.runSequentially(SuiteRunner.java:352)
	at org.testng.SuiteRunner.privateRun(SuiteRunner.java:310)
	at org.testng.SuiteRunner.run(SuiteRunner.java:259)
	at org.testng.SuiteRunnerWorker.runSuite(SuiteRunnerWorker.java:52)
	at org.testng.SuiteRunnerWorker.run(SuiteRunnerWorker.java:86)
	at org.testng.TestNG.runSuitesSequentially(TestNG.java:1200)
	at org.testng.TestNG.runSuitesLocally(TestNG.java:1125)
	at org.testng.TestNG.run(TestNG.java:1033)
	at org.testng.remote.RemoteTestNG.run(RemoteTestNG.java:111)
	at org.testng.remote.RemoteTestNG.initAndRun(RemoteTestNG.java:204)
	at org.testng.remote.RemoteTestNG.main(RemoteTestNG.java:175)
]]>
    </error>
  </testcase> <!-- subTest -->
  <testcase name="mulTest" time="0.013" classname="com.example1.calculateTest$calcTest"/>
</testsuite> <!-- com.example1.calculateTest$calcTest -->
